Workbook

Sheet 종합
A1: 분할별 구간 평균 클럭 종합 (분할마다 대표 실행 하나, 재측정이 있으면 가장 최근 판)
A2: 기본 클럭(GHz) | B2: 2.69 | C2: GHz = typeperf 백분율의 구간 평균 × 기본 클럭 ÷ 100. 동시 실행 = 분할과 병렬도 중 작은 쪽.
A4: 분할 | B4: 동시 실행(병렬도 6) | C4: 동시 실행(병렬도 12) | D4: 순차(GHz) | E4: 병렬도 6(GHz) | F4: 병렬도 12(GHz) | G4: 순차 대비 하락, 병렬도 6(%) | H4: 순차 대비 하락, 병렬도 12(%) | I4: 표본 수(순차) | J4: 표본 수(병렬 6) | K4: 표본 수(병렬 12) | L4: 대표 실행 파일
A5: 1 | B5: 1 | C5: 1 | D5: 4.2601851 | E5: 4.252407 | F5: 4.2565659 | G5: =(D5-E5)/D5*100 | H5: =(D5-F5)/D5*100 | I5: 27 | J5: 35 | K5: 34 | L5: 병렬도6과12_말단작업분할수준_1_원본데이터_3
A6: 2 | B6: 2 | C6: 2 | D6: 4.1737949 | E6: 4.2329189 | F6: 4.2330466 | G6: =(D6-E6)/D6*100 | H6: =(D6-F6)/D6*100 | I6: 26 | J6: 17 | K6: 17 | L6: 병렬도6과12_말단작업분할수준_2_원본데이터
A7: 3 | B7: 3 | C7: 3 | D7: 4.2069203 | E7: 4.1972042 | F7: 4.1722433 | G7: =(D7-E7)/D7*100 | H7: =(D7-F7)/D7*100 | I7: 28 | J7: 18 | K7: 18 | L7: 병렬도6과12_말단작업분할수준_3_원본데이터
A8: 4 | B8: 4 | C8: 4 | D8: 4.2279036 | E8: 4.1439463 | F8: 4.1324397 | G8: =(D8-E8)/D8*100 | H8: =(D8-F8)/D8*100 | I8: 26 | J8: 17 | K8: 16 | L8: 병렬도6과12_말단작업분할수준_4_원본데이터
A9: 5 | B9: 5 | C9: 5 | D9: 4.254359 | E9: 4.0941646 | F9: 4.0910768 | G9: =(D9-E9)/D9*100 | H9: =(D9-F9)/D9*100 | I9: 23 | J9: 11 | K9: 10 | L9: 병렬도6과12_말단작업분할수준_5_원본데이터
A10: 6 | B10: 6 | C10: 6 | D10: 4.2203544 | E10: 4.0861136 | F10: 4.084966 | G10: =(D10-E10)/D10*100 | H10: =(D10-F10)/D10*100 | I10: 27 | J10: 15 | K10: 16 | L10: 병렬도6과12_말단작업분할수준_6_원본데이터
A11: 7 | B11: 6 | C11: 7 | D11: 4.2186327 | E11: 4.0936418 | F11: 4.0629832 | G11: =(D11-E11)/D11*100 | H11: =(D11-F11)/D11*100 | I11: 24 | J11: 12 | K11: 10 | L11: 병렬도6과12_말단작업분할수준_7_원본데이터
A12: 8 | B12: 6 | C12: 8 | D12: 4.1984119 | E12: 4.0934188 | F12: 4.0551504 | G12: =(D12-E12)/D12*100 | H12: =(D12-F12)/D12*100 | I12: 24 | J12: 12 | K12: 10 | L12: 병렬도6과12_말단작업분할수준_8_원본데이터
A13: 9 | B13: 6 | C13: 9 | D13: 4.1532591 | E13: 4.1101363 | F13: 4.0830355 | G13: =(D13-E13)/D13*100 | H13: =(D13-F13)/D13*100 | I13: 29 | J13: 16 | K13: 13 | L13: 병렬도6과12_말단작업분할수준_9_원본데이터
A14: 10 | B14: 6 | C14: 10 | D14: 4.2434739 | E14: 4.1020671 | F14: 4.0821516 | G14: =(D14-E14)/D14*100 | H14: =(D14-F14)/D14*100 | I14: 26 | J14: 16 | K14: 13 | L14: 병렬도6과12_말단작업분할수준_10_원본데이터
A15: 11 | B15: 6 | C15: 11 | D15: 4.2052898 | E15: 4.0916426 | F15: 4.0584413 | G15: =(D15-E15)/D15*100 | H15: =(D15-F15)/D15*100 | I15: 26 | J15: 14 | K15: 11 | L15: 병렬도6과12_말단작업분할수준_11_원본데이터
A16: 12 | B16: 6 | C16: 12 | D16: 4.2337819 | E16: 4.0888684 | F16: 4.0806649 | G16: =(D16-E16)/D16*100 | H16: =(D16-F16)/D16*100 | I16: 28 | J16: 16 | K16: 12 | L16: 병렬도6과12_말단작업분할수준_12_원본데이터
... A19: 36 | B19: 6 | C19: 12 | D19: 4.1683095 | E19: 4.0718206 | F19: 4.0772375 | G19: =(D19-E19)/D19*100 | H19: =(D19-F19)/D19*100 | I19: 28 | J19: 15 | K19: 12 | L19: 병렬도6과12_말단작업분할수준_36_원본데이터

Sheet 구간 상세
A1: 실행(파일)별 세 구간의 시각 경계와 표본. 대표 = 종합 시트에 쓴 실행.
A3: 분할 | B3: 실행 파일 | C3: 대표 | D3: 구간 | E3: 시작 | F3: 끝 | G3: 길이(초) | H3: 표본 수(개) | I3: 평균(%) | J3: 평균(GHz) | K3: 최소(GHz) | L3: 최대(GHz)
A4: 1 | B4: 병렬도6과12_말단작업분할수준_1_원본데이터_3 | C4: 대표 | D4: 순차 | E4: 11:07:45.358 | F4: 11:08:12.458 | G4: 27.100225 | H4: 27 | I4: 158.37119 | J4: =I4*'종합'!$B$2/100 | K4: 4.0927814 | L4: 4.3254904
A5: 1 | B5: 병렬도6과12_말단작업분할수준_1_원본데이터_3 | C5: 대표 | D5: 병렬도 6 분할 1 | E5: 11:08:12.459 | F5: 11:08:47.783 | G5: 35.324269 | H5: 35 | I5: 158.08204 | J5: =I5*'종합'!$B$2/100 | K5: 4.0812907 | L5: 4.3044878
A6: 1 | B6: 병렬도6과12_말단작업분할수준_1_원본데이터_3 | C6: 대표 | D6: 병렬도 12 분할 1 | E6: 11:08:47.784 | F6: 11:09:22.553 | G6: 34.768686 | H6: 34 | I6: 158.23665 | J6: =I6*'종합'!$B$2/100 | K6: 4.0826518 | L6: 4.3141705
A7: 2 | B7: 병렬도6과12_말단작업분할수준_2_원본데이터 | C7: 대표 | D7: 순차 | E7: 10:44:48.707 | F7: 10:45:15.152 | G7: 26.444701 | H7: 26 | I7: 155.15966 | J7: =I7*'종합'!$B$2/100 | K7: 4.0600706 | L7: 4.2950733
A8: 2 | B8: 병렬도6과12_말단작업분할수준_2_원본데이터 | C8: 대표 | D8: 병렬도 6 분할 2 | E8: 10:45:15.152 | F8: 10:45:32.055 | G8: 16.903362 | H8: 17 | I8: 157.35758 | J8: =I8*'종합'!$B$2/100 | K8: 4.1534297 | L8: 4.2704284
A9: 2 | B9: 병렬도6과12_말단작업분할수준_2_원본데이터 | C9: 대표 | D9: 병렬도 12 분할 2 | E9: 10:45:32.055 | F9: 10:45:49.071 | G9: 17.016035 | H9: 17 | I9: 157.36233 | J9: =I9*'종합'!$B$2/100 | K9: 4.1515168 | L9: 4.2662261
A10: 3 | B10: 병렬도6과12_말단작업분할수준_3_원본데이터 | C10: 대표 | D10: 순차 | E10: 11:28:39.229 | F10: 11:29:07.155 | G10: 27.925411 | H10: 28 | I10: 156.39109 | J10: =I10*'종합'!$B$2/100 | K10: 4.0844639 | L10: 4.2830831
A11: 3 | B11: 병렬도6과12_말단작업분할수준_3_원본데이터 | C11: 대표 | D11: 병렬도 6 분할 3 | E11: 11:29:07.155 | F11: 11:29:25.399 | G11: 18.244637 | H11: 18 | I11: 156.0299 | J11: =I11*'종합'!$B$2/100 | K11: 4.1318056 | L11: 4.224281
A12: 3 | B12: 병렬도6과12_말단작업분할수준_3_원본데이터 | C12: 대표 | D12: 병렬도 12 분할 3 | E12: 11:29:25.399 | F12: 11:29:43.749 | G12: 18.350191 | H12: 18 | I12: 155.10198 | J12: =I12*'종합'!$B$2/100 | K12: 4.0988506 | L12: 4.2361797
A13: 4 | B13: 병렬도6과12_말단작업분할수준_4_원본데이터 | C13: 대표 | D13: 순차 | E13: 11:36:51.310 | F13: 11:37:17.885 | G13: 26.574736 | H13: 26 | I13: 157.17114 | J13: =I13*'종합'!$B$2/100 | K13: 4.0936136 | L13: 4.2844114
A14: 4 | B14: 병렬도6과12_말단작업분할수준_4_원본데이터 | C14: 대표 | D14: 병렬도 6 분할 4 | E14: 11:37:17.886 | F14: 11:37:34.697 | G14: 16.811289 | H14: 17 | I14: 154.05005 | J14: =I14*'종합'!$B$2/100 | K14: 4.1158042 | L14: 4.217333
A15: 4 | B15: 병렬도6과12_말단작업분할수준_4_원본데이터 | C15: 대표 | D15: 병렬도 12 분할 4 | E15: 11:37:34.697 | F15: 11:37:51.443 | G15: 16.745928 | H15: 16 | I15: 153.62229 | J15: =I15*'종합'!$B$2/100 | K15: 4.0955232 | L15: 4.1630521
... A48: 36 | B48: 병렬도6과12_말단작업분할수준_36_원본데이터 | C48: 대표 | D48: 병렬도 12 분할 36 | E48: 12:33:55.154 | F48: 12:34:07.232 | G48: 12.077799 | H48: 12 | I48: 151.57017 | J48: =I48*'종합'!$B$2/100 | K48: 4.0183975 | L48: 4.0833249

Sheet 회차별 원값 종합
A1: 모든 실행의 IMPLOG run 레코드(측정 회차별 원값). run 레코드가 없는 옛 로그 실행은 여기 없다.
A2: busyCore = procCPU ÷ elapsed. speedup = 같은 실행의 순차 elapsed 5회 평균 ÷ 그 행 elapsed. 스레드 CPU 시간은 Windows 해상도(15.625ms) 계단이라 작은 값은 0으로 찍힌다.
A4: 분할 | B4: 실행 파일 | C4: 대표 | D4: 구현 | E4: 병렬도 | F4: 회차 | G4: elapsed(ms) | H4: procCPU(ms) | I4: busyCore(개) | J4: mainCPU(ms) | K4: workerCPU(ms) | L4: 기타 자바(ms) | M4: 자바 아닌(ms) | N4: GC(ms) | O4: speedup(배)
A5: 1 | B5: 병렬도6과12_말단작업분할수준_1_원본데이터_3 | C5: 대표 | D5: 순차 | E5: - | F5: 1 | G5: 3279.3254 | H5: 3281.25 | I5: =H5/G5 | J5: 3250 | K5: 0 | L5: 0 | M5: 31.25 | N5: 18
A6: 1 | B6: 병렬도6과12_말단작업분할수준_1_원본데이터_3 | C6: 대표 | D6: 순차 | E6: - | F6: 2 | G6: 4187.6967 | H6: 4203.125 | I6: =H6/G6 | J6: 4140.625 | K6: 0 | L6: 0 | M6: 62.5 | N6: 17
A7: 1 | B7: 병렬도6과12_말단작업분할수준_1_원본데이터_3 | C7: 대표 | D7: 순차 | E7: - | F7: 3 | G7: 4668.4591 | H7: 4421.875 | I7: =H7/G7 | J7: 4421.875 | K7: 0 | L7: 0 | M7: 0 | N7: 26
A8: 1 | B8: 병렬도6과12_말단작업분할수준_1_원본데이터_3 | C8: 대표 | D8: 순차 | E8: - | F8: 4 | G8: 4105.3059 | H8: 4109.375 | I8: =H8/G8 | J8: 4109.375 | K8: 0 | L8: 0 | M8: 0 | N8: 17
A9: 1 | B9: 병렬도6과12_말단작업분할수준_1_원본데이터_3 | C9: 대표 | D9: 순차 | E9: - | F9: 5 | G9: 4119.8559 | H9: 4078.125 | I9: =H9/G9 | J9: 4078.125 | K9: 0 | L9: 0 | M9: 0 | N9: 16
A10: 1 | B10: 병렬도6과12_말단작업분할수준_1_원본데이터_3 | C10: 대표 | D10: 병렬 | E10: 6 | F10: 1 | G10: 4302.2455 | H10: 4734.375 | I10: =H10/G10 | J10: 0 | K10: 4296.875 | L10: 0 | M10: 437.5 | N10: 20 | O10: 0.94651237
A11: 1 | B11: 병렬도6과12_말단작업분할수준_1_원본데이터_3 | C11: 대표 | D11: 병렬 | E11: 6 | F11: 2 | G11: 4213.1587 | H11: 4343.75 | I11: =H11/G11 | J11: 0 | K11: 4156.25 | L11: 0 | M11: 187.5 | N11: 17 | O11: 0.96652628
A12: 1 | B12: 병렬도6과12_말단작업분할수준_1_원본데이터_3 | C12: 대표 | D12: 병렬 | E12: 6 | F12: 3 | G12: 4672.348 | H12: 4453.125 | I12: =H12/G12 | J12: 0 | K12: 4359.375 | L12: 0 | M12: 93.75 | N12: 18 | O12: 0.87153795
A13: 1 | B13: 병렬도6과12_말단작업분할수준_1_원본데이터_3 | C13: 대표 | D13: 병렬 | E13: 6 | F13: 4 | G13: 4234.6782 | H13: 4250 | I13: =H13/G13 | J13: 0 | K13: 4218.75 | L13: 0 | M13: 31.25 | N13: 18 | O13: 0.96161465
A14: 1 | B14: 병렬도6과12_말단작업분할수준_1_원본데이터_3 | C14: 대표 | D14: 병렬 | E14: 6 | F14: 5 | G14: 4243.7282 | H14: 4234.375 | I14: =H14/G14 | J14: 0 | K14: 4234.375 | L14: 0 | M14: 0 | N14: 17 | O14: 0.95956395
A15: 1 | B15: 병렬도6과12_말단작업분할수준_1_원본데이터_3 | C15: 대표 | D15: 병렬 | E15: 12 | F15: 1 | G15: 4278.3612 | H15: 4453.125 | I15: =H15/G15 | J15: 0 | K15: 4250 | L15: 0 | M15: 203.125 | N15: 17 | O15: 0.95179636
A16: 1 | B16: 병렬도6과12_말단작업분할수준_1_원본데이터_3 | C16: 대표 | D16: 병렬 | E16: 12 | F16: 2 | G16: 4759.4984 | H16: 4421.875 | I16: =H16/G16 | J16: 0 | K16: 4328.125 | L16: 0 | M16: 93.75 | N16: 18 | O16: 0.85557936
A17: 1 | B17: 병렬도6과12_말단작업분할수준_1_원본데이터_3 | C17: 대표 | D17: 병렬 | E17: 12 | F17: 3 | G17: 4252.4766 | H17: 4250 | I17: =H17/G17 | J17: 0 | K17: 4203.125 | L17: 0 | M17: 46.875 | N17: 18 | O17: 0.95758989
A18: 1 | B18: 병렬도6과12_말단작업분할수준_1_원본데이터_3 | C18: 대표 | D18: 병렬 | E18: 12 | F18: 4 | G18: 4218.1471 | H18: 4203.125 | I18: =H18/G18 | J18: 0 | K18: 4203.125 | L18: 0 | M18: 0 | N18: 17 | O18: 0.96538326
A19: 1 | B19: 병렬도6과12_말단작업분할수준_1_원본데이터_3 | C19: 대표 | D19: 병렬 | E19: 12 | F19: 5 | G19: 4620.5482 | H19: 4343.75 | I19: =H19/G19 | J19: 0 | K19: 4328.125 | L19: 0 | M19: 15.625 | N19: 18 | O19: 0.88130854
A20: 2 | B20: 병렬도6과12_말단작업분할수준_2_원본데이터 | C20: 대표 | D20: 순차 | E20: - | F20: 1 | G20: 3923.7311 | H20: 4171.875 | I20: =H20/G20 | J20: 3890.625 | K20: 0 | L20: 0 | M20: 281.25 | N20: 16
A21: 2 | B21: 병렬도6과12_말단작업분할수준_2_원본데이터 | C21: 대표 | D21: 순차 | E21: - | F21: 2 | G21: 3857.6964 | H21: 4062.5 | I21: =H21/G21 | J21: 3843.75 | K21: 0 | L21: 0 | M21: 218.75 | N21: 18
A22: 2 | B22: 병렬도6과12_말단작업분할수준_2_원본데이터 | C22: 대표 | D22: 순차 | E22: - | F22: 3 | G22: 4165.5424 | H22: 3875 | I22: =H22/G22 | J22: 3843.75 | K22: 0 | L22: 0 | M22: 31.25 | N22: 17
A23: 2 | B23: 병렬도6과12_말단작업분할수준_2_원본데이터 | C23: 대표 | D23: 순차 | E23: - | F23: 4 | G23: 3662.3205 | H23: 3625 | I23: =H23/G23 | J23: 3625 | K23: 0 | L23: 0 | M23: 0 | N23: 18
A24: 2 | B24: 병렬도6과12_말단작업분할수준_2_원본데이터 | C24: 대표 | D24: 순차 | E24: - | F24: 5 | G24: 3644.0684 | H24: 3734.375 | I24: =H24/G24 | J24: 3609.375 | K24: 0 | L24: 0 | M24: 125 | N24: 18
A25: 2 | B25: 병렬도6과12_말단작업분할수준_2_원본데이터 | C25: 대표 | D25: 병렬 | E25: 6 | F25: 1 | G25: 2127.3049 | H25: 4609.375 | I25: =H25/G25 | J25: 0 | K25: 4203.125 | L25: 0 | M25: 406.25 | N25: 18 | O25: 1.8101175
A26: 2 | B26: 병렬도6과12_말단작업분할수준_2_원본데이터 | C26: 대표 | D26: 병렬 | E26: 6 | F26: 2 | G26: 2070.0765 | H26: 3937.5 | I26: =H26/G26 | J26: 15.625 | K26: 3890.625 | L26: 0 | M26: 31.25 | N26: 18 | O26: 1.8601592
A27: 2 | B27: 병렬도6과12_말단작업분할수준_2_원본데이터 | C27: 대표 | D27: 병렬 | E27: 6 | F27: 3 | G27: 2107.3829 | H27: 4156.25 | I27: =H27/G27 | J27: 15.625 | K27: 4109.375 | L27: 0 | M27: 31.25 | N27: 18 | O27: 1.8272293
A28: 2 | B28: 병렬도6과12_말단작업분할수준_2_원본데이터 | C28: 대표 | D28: 병렬 | E28: 6 | F28: 4 | G28: 2064.7505 | H28: 4046.875 | I28: =H28/G28 | J28: 0 | K28: 4031.25 | L28: 0 | M28: 15.625 | N28: 18 | O28: 1.8649574
A29: 2 | B29: 병렬도6과12_말단작업분할수준_2_원본데이터 | C29: 대표 | D29: 병렬 | E29: 6 | F29: 5 | G29: 2107.0946 | H29: 4046.875 | I29: =H29/G29 | J29: 0 | K29: 3984.375 | L29: 0 | M29: 46.875 | N29: 19 | O29: 1.8274793
A30: 2 | B30: 병렬도6과12_말단작업분할수준_2_원본데이터 | C30: 대표 | D30: 병렬 | E30: 12 | F30: 1 | G30: 2062.8139 | H30: 3984.375 | I30: =H30/G30 | J30: 0 | K30: 3953.125 | L30: 0 | M30: 31.25 | N30: 18 | O30: 1.8667083
A31: 2 | B31: 병렬도6과12_말단작업분할수준_2_원본데이터 | C31: 대표 | D31: 병렬 | E31: 12 | F31: 2 | G31: 2083.2645 | H31: 4000 | I31: =H31/G31 | J31: 15.625 | K31: 3968.75 | L31: 0 | M31: 15.625 | N31: 18 | O31: 1.8483835
A32: 2 | B32: 병렬도6과12_말단작업분할수준_2_원본데이터 | C32: 대표 | D32: 병렬 | E32: 12 | F32: 3 | G32: 2103.5188 | H32: 4093.75 | I32: =H32/G32 | J32: 15.625 | K32: 4031.25 | L32: 0 | M32: 46.875 | N32: 19 | O32: 1.8305859
A33: 2 | B33: 병렬도6과12_말단작업분할수준_2_원본데이터 | C33: 대표 | D33: 병렬 | E33: 12 | F33: 4 | G33: 2138.7423 | H33: 4156.25 | I33: =H33/G33 | J33: 0 | K33: 4109.375 | L33: 0 | M33: 46.875 | N33: 21 | O33: 1.8004375
A34: 2 | B34: 병렬도6과12_말단작업분할수준_2_원본데이터 | C34: 대표 | D34: 병렬 | E34: 12 | F34: 5 | G34: 2136.2267 | H34: 4156.25 | I34: =H34/G34 | J34: 0 | K34: 4140.625 | L34: 0 | M34: 15.625 | N34: 20 | O34: 1.8025576
A35: 3 | B35: 병렬도6과12_말단작업분할수준_3_원본데이터 | C35: 대표 | D35: 순차 | E35: - | F35: 1 | G35: 3254.5232 | H35: 3359.375 | I35: =H35/G35 | J35: 3234.375 | K35: 0 | L35: 0 | M35: 125 | N35: 18
A36: 3 | B36: 병렬도6과12_말단작업분할수준_3_원본데이터 | C36: 대표 | D36: 순차 | E36: - | F36: 2 | G36: 4177.3218 | H36: 4218.75 | I36: =H36/G36 | J36: 4140.625 | K36: 0 | L36: 0 | M36: 78.125 | N36: 19
A37: 3 | B37: 병렬도6과12_말단작업분할수준_3_원본데이터 | C37: 대표 | D37: 순차 | E37: - | F37: 3 | G37: 4278.65 | H37: 4296.875 | I37: =H37/G37 | J37: 4281.25 | K37: 0 | L37: 0 | M37: 15.625 | N37: 16
A38: 3 | B38: 병렬도6과12_말단작업분할수준_3_원본데이터 | C38: 대표 | D38: 순차 | E38: - | F38: 4 | G38: 4746.1911 | H38: 4437.5 | I38: =H38/G38 | J38: 4437.5 | K38: 0 | L38: 0 | M38: 0 | N38: 25
A39: 3 | B39: 병렬도6과12_말단작업분할수준_3_원본데이터 | C39: 대표 | D39: 순차 | E39: - | F39: 5 | G39: 4229.3282 | H39: 4218.75 | I39: =H39/G39 | J39: 4187.5 | K39: 0 | L39: 0 | M39: 31.25 | N39: 18
A40: 3 | B40: 병렬도6과12_말단작업분할수준_3_원본데이터 | C40: 대표 | D40: 병렬 | E40: 6 | F40: 1 | G40: 2251.0868 | H40: 6718.75 | I40: =H40/G40 | J40: 62.5 | K40: 6140.625 | L40: 0 | M40: 515.625 | N40: 18 | O40: 1.8378691
A41: 3 | B41: 병렬도6과12_말단작업분할수준_3_원본데이터 | C41: 대표 | D41: 병렬 | E41: 6 | F41: 2 | G41: 2251.1889 | H41: 6359.375 | I41: =H41/G41 | J41: 15.625 | K41: 6328.125 | L41: 0 | M41: 15.625 | N41: 19 | O41: 1.8377857
...

Sheet 차트
A1: 첫 그래프의 원천은 종합 시트(구간 평균 클럭)이고, 지표별 그래프의 원천은 차트 데이터 시트다. 가로축은 모두 분할 개수다.

Sheet 차트 데이터
A1: 차트 시트 지표별 그래프의 원천 표다. 값은 분할마다 대표 실행의 병렬 측정 5회 평균(IMPLOG run 레코드)이고, busyCore는 procCPU 평균을 elapsed 평균으로 나눈 값이다. run 레코드가 없는 분할은 빈 칸이다.
A3: elapsed(ms) | E3: procCPU(ms) | I3: busyCore(개) | M3: mainCPU(ms) | Q3: workerCPU(ms) | U3: 기타 자바(ms) | Y3: 자바 아닌(ms)
A4: 분할 | B4: 병렬도 6 | C4: 병렬도 12 | E4: 분할 | F4: 병렬도 6 | G4: 병렬도 12 | I4: 분할 | J4: 병렬도 6 | K4: 병렬도 12 | M4: 분할 | N4: 병렬도 6 | O4: 병렬도 12 | Q4: 분할 | R4: 병렬도 6 | S4: 병렬도 12 | U4: 분할 | V4: 병렬도 6 | W4: 병렬도 12 | Y4: 분할 | Z4: 병렬도 6 | AA4: 병렬도 12
A5: 1 | B5: 4333.2317 | C5: 4425.8063 | E5: 1 | F5: 4403.125 | G5: 4334.375 | I5: 1 | J5: 1.0161296 | K5: 0.97934132 | M5: 1 | N5: 0 | O5: 0 | Q5: 1 | R5: 4253.125 | S5: 4262.5 | U5: 1 | V5: 0 | W5: 0 | Y5: 1 | Z5: 150 | AA5: 71.875
A6: 2 | B6: 2095.3219 | C6: 2104.9132 | E6: 2 | F6: 4159.375 | G6: 4078.125 | I6: 2 | J6: 1.9850769 | K6: 1.9374314 | M6: 2 | N6: 6.25 | O6: 6.25 | Q6: 2 | R6: 4043.75 | S6: 4040.625 | U6: 2 | V6: 0 | W6: 0 | Y6: 2 | Z6: 106.25 | AA6: 31.25
A7: 3 | B7: 2258.5778 | C7: 2311.4788 | E7: 3 | F7: 6453.125 | G7: 6668.75 | I7: 3 | J7: 2.8571631 | K7: 2.8850579 | M7: 3 | N7: 18.75 | O7: 0 | Q7: 3 | R7: 6300 | S7: 6593.75 | U7: 3 | V7: 0 | W7: 0 | Y7: 3 | Z7: 134.375 | AA7: 75
A8: 4 | B8: 2082.4376 | C8: 2093.9886 | E8: 4 | F8: 7950 | G8: 7890.625 | I8: 4 | J8: 3.8176415 | K8: 3.7682273 | M8: 4 | N8: 6.25 | O8: 3.125 | Q8: 4 | R8: 7768.75 | S8: 7840.625 | U8: 4 | V8: 0 | W8: 0 | Y8: 4 | Z8: 171.875 | AA8: 46.875
A9: 5 | B9: 1348.6426 | C9: 1342.862 | E9: 5 | F9: 6290.625 | G9: 6187.5 | I9: 5 | J9: 4.6644123 | K9: 4.6076962 | M9: 5 | N9: 6.25 | O9: 9.375 | Q9: 5 | R9: 6103.125 | S9: 6096.875 | U9: 5 | V9: 0 | W9: 0 | Y9: 5 | Z9: 181.25 | AA9: 81.25
A10: 6 | B10: 1961.2646 | C10: 1962.9408 | E10: 6 | F10: 10856.25 | G10: 11025 | I10: 6 | J10: 5.5353318 | K10: 5.6165727 | M10: 6 | N10: 6.25 | O10: 6.25 | Q10: 6 | R10: 10659.375 | S10: 10893.75 | U10: 6 | V10: 0 | W10: 0 | Y10: 6 | Z10: 190.625 | AA10: 125
A11: 7 | B11: 1521.2336 | C11: 1268.5743 | E11: 7 | F11: 6831.25 | G11: 7731.25 | I11: 7 | J11: 4.4905989 | K11: 6.0944398 | M11: 7 | N11: 6.25 | O11: 3.125 | Q11: 7 | R11: 6684.375 | S11: 7646.875 | U11: 7 | V11: 0 | W11: 0 | Y11: 7 | Z11: 140.625 | AA11: 81.25
A12: 8 | B12: 1531.1531 | C12: 1189.4947 | E12: 8 | F12: 6571.875 | G12: 8662.5 | I12: 8 | J12: 4.2921083 | K12: 7.2825042 | M12: 8 | N12: 9.375 | O12: 0 | Q12: 8 | R12: 6331.25 | S12: 8603.125 | U12: 8 | V12: 0 | W12: 0 | Y12: 8 | Z12: 231.25 | AA12: 59.375
A13: 9 | B13: 2107.5521 | C13: 1631.4631 | E13: 9 | F13: 9587.5 | G13: 13503.125 | I13: 9 | J13: 4.5491165 | K13: 8.2766967 | M13: 9 | N13: 3.125 | O13: 3.125 | Q13: 9 | R13: 9450 | S13: 13415.625 | U13: 9 | V13: 0 | W13: 0 | Y13: 9 | Z13: 134.375 | AA13: 84.375
A14: 10 | B14: 2028.9573 | C14: 1541.2099 | E14: 10 | F14: 10221.875 | G14: 14259.375 | I14: 10 | J14: 5.0379941 | K14: 9.2520653 | M14: 10 | N14: 3.125 | O14: 6.25 | Q14: 10 | R14: 10031.25 | S14: 14212.5 | U14: 10 | V14: 0 | W14: 0 | Y14: 10 | Z14: 187.5 | AA14: 40.625
A15: 11 | B15: 1678.0625 | C15: 1415.9402 | E15: 11 | F15: 8615.625 | G15: 13146.875 | I15: 11 | J15: 5.1342694 | K15: 9.2849082 | M15: 11 | N15: 3.125 | O15: 3.125 | Q15: 11 | R15: 8403.125 | S15: 12984.375 | U15: 11 | V15: 0 | W15: 0 | Y15: 11 | Z15: 209.375 | AA15: 159.375
A16: 12 | B16: 2020.227 | C16: 1521.5534 | E16: 12 | F16: 10431.25 | G16: 14790.625 | I16: 12 | J16: 5.1634048 | K16: 9.7207399 | M16: 12 | N16: 3.125 | O16: 3.125 | Q16: 12 | R16: 10140.625 | S16: 14656.25 | U16: 12 | V16: 0 | W16: 0 | Y16: 12 | Z16: 287.5 | AA16: 128.125
... A19: 36 | B19: 1968.2899 | C19: 1493.4223 | E19: 36 | F19: 10668.75 | G19: 14425 | I19: 36 | J19: 5.4203144 | K19: 9.6590226 | M19: 36 | N19: 6.25 | O19: 3.125 | Q19: 36 | R19: 10318.75 | S19: 14359.375 | U19: 36 | V19: 0 | W19: 0 | Y19: 36 | Z19: 343.75 | AA19: 62.5
