Workbook

Sheet 클럭 정리
A1: 논리 프로세서별 CPU 클럭, 표본 간격은 기록 도구 설정 (typeperf % Processor Performance)
A2: 기본 클럭(GHz) | B2: 2.69 | C2: 출처: 작업 관리자 성능 탭의 기본 속도. GHz = 백분율 × 기본 클럭 ÷ 100
A3: 각 표본은 그 시각까지의 직전 표본 간격 구간의 평균이다. 백분율은 기본 클럭 대비 값이라 터보 구간에서 100을 넘는다.
A5: 시각 | B5: 논리 0(%) | C5: 논리 1(%) | D5: 논리 2(%) | E5: 논리 3(%) | F5: 논리 4(%) | G5: 논리 5(%) | H5: 논리 6(%) | I5: 논리 7(%) | J5: 논리 8(%) | K5: 논리 9(%) | L5: 논리 10(%) | M5: 논리 11(%) | N5: 전체 평균(%) | O5: 전체 평균(GHz)
A6: 46238.488 | B6: 143.94823 | C6: 156.69652 | D6: 146.42701 | E6: 139.82252 | F6: 139.7231 | G6: 145.31505 | H6: 154.39604 | I6: 141.29428 | J6: 143.78667 | K6: 139.13291 | L6: 140.26178 | M6: 139.11862 | N6: 146.59695 | O6: =N6*$B$2/100
A7: 46238.488 | B7: 152.04212 | C7: 153.36597 | D7: 152.626 | E7: 151.74452 | F7: 151.62563 | G7: 151.64589 | H7: 151.28129 | I7: 151.4209 | J7: 151.17765 | K7: 151.50532 | L7: 150.49596 | M7: 151.68751 | N7: 151.76665 | O7: =N7*$B$2/100
A8: 46238.488 | B8: 151.8959 | C8: 150.58704 | D8: 150.7695 | E8: 150.75512 | F8: 151.49513 | G8: 142.69302 | H8: 147.59254 | I8: 147.13706 | J8: 148.73521 | K8: 150.93785 | L8: 150.21542 | M8: 152.5619 | N8: 150.09622 | O8: =N8*$B$2/100
A9: 46238.488 | B9: 154.73746 | C9: 157.27962 | D9: 154.27504 | E9: 151.0918 | F9: 153.97897 | G9: 151.5042 | H9: 147.79697 | I9: 160.4535 | J9: 149.76369 | K9: 150.85586 | L9: 154.7026 | M9: 156.82261 | N9: 154.02977 | O9: =N9*$B$2/100
A10: 46238.488 | B10: 159.52104 | C10: 160.16313 | D10: 147.82043 | E10: 161.49795 | F10: 154.33249 | G10: 139.33999 | H10: 151.38451 | I10: 153.48427 | J10: 159.1492 | K10: 141.68768 | L10: 159.89297 | M10: 160.78564 | N10: 158.09135 | O10: =N10*$B$2/100
A11: 46238.488 | B11: 157.97146 | C11: 159.50735 | D11: 159.81896 | E11: 158.68547 | F11: 155.04956 | G11: 149.2986 | H11: 147.18771 | I11: 151.6006 | J11: 151.75365 | K11: 128.83653 | L11: 160.48403 | M11: 156.48475 | N11: 157.72964 | O11: =N11*$B$2/100
A12: 46238.488 | B12: 159.7253 | C12: 158.96148 | D12: 157.18589 | E12: 132.21944 | F12: 147.29989 | G12: 142.26039 | H12: 154.30306 | I12: 121.66452 | J12: 155.40392 | K12: 145.25991 | L12: 160.40706 | M12: 159.5436 | N12: 157.69256 | O12: =N12*$B$2/100
A13: 46238.488 | B13: 161.30504 | C13: 161.36849 | D13: 155.82539 | E13: 158.82924 | F13: 148.41728 | G13: 139.87224 | H13: 157.54651 | I13: 111.43306 | J13: 161.06247 | K13: 149.70273 | L13: 159.27078 | M13: 161.29133 | N13: 158.91691 | O13: =N13*$B$2/100
A14: 46238.488 | B14: 161.93968 | C14: 159.69558 | D14: 158.05904 | E14: 158.3255 | F14: 154.65973 | G14: 157.89522 | H14: 151.31207 | I14: 128.56119 | J14: 152.55389 | K14: 134.78767 | L14: 159.45482 | M14: 160.62609 | N14: 158.41992 | O14: =N14*$B$2/100
A15: 46238.488 | B15: 160.23807 | C15: 159.9113 | D15: 151.53126 | E15: 156.20198 | F15: 143.93931 | G15: 158.60939 | H15: 153.74959 | I15: 128.23633 | J15: 152.05165 | K15: 157.55182 | L15: 160.82391 | M15: 161.65845 | N15: 158.29443 | O15: =N15*$B$2/100
A16: 46238.488 | B16: 158.60327 | C16: 153.12937 | D16: 152.49656 | E16: 123.87658 | F16: 151.14278 | G16: 149.19296 | H16: 151.10658 | I16: 112.94332 | J16: 160.24612 | K16: 156.17568 | L16: 159.96133 | M16: 160.13157 | N16: 157.6252 | O16: =N16*$B$2/100
A17: 46238.488 | B17: 160.24189 | C17: 162.36133 | D17: 159.5202 | E17: 129.95357 | F17: 140.70881 | G17: 146.33408 | H17: 153.25899 | I17: 115.76261 | J17: 151.3994 | K17: 129.60141 | L17: 160.9951 | M17: 159.59509 | N17: 158.29766 | O17: =N17*$B$2/100
... A60: 46238.488 | B60: 123.24428 | C60: 158.46194 | D60: 158.27969 | E60: 127.63153 | F60: 130.43893 | G60: 123.50449 | H60: 150.16056 | I60: 155.55547 | J60: 147.11765 | K60: 125.51091 | L60: 130.94402 | M60: 127.43976 | N60: 148.79059 | O60: =N60*$B$2/100

Sheet 구간과 스레드 매핑
A1: 테스트 구간별 시각 경계와 실행 스레드, 그 구간의 평균 클럭
A2: 시각 경계 출처: 전체·워밍업·워커 읽기는 프로브의 [구간 시각] 출력, 측정 회차는 IMPLOG의 시작시각ms(첫 스캔 시작)와 마지막 스캔 시작+바퀴 시간이다.
A3: 클럭은 논리 프로세서별 값이고 스레드가 어느 프로세서에서 돌았는지는 기록되지 않으므로, 스레드별 대응은 구간 단위까지다. 각 표본이 직전 간격의 평균이라 경계 표본에는 이웃 구간의 몫이 섞일 수 있다.
A5: 구간 | B5: 시작 시각 | C5: 끝 시각 | D5: 길이(초) | E5: 실행 스레드 | F5: 표본 수(개) | G5: 평균 클럭(%) | H5: 평균 클럭(GHz)
A6: 순차 전체 | B6: 46238.488 | C6: 46238.488 | D6: =(C6-B6)*86400 | E6: main (improveSequential, 워밍업+측정) | F6: =COUNTIFS('클럭 정리'!$A$6:$A$60,">="&B6,'클럭 정리'!$A$6:$A$60,"<="&C6) | G6: =AVERAGEIFS('클럭 정리'!$N$6:$N$60,'클럭 정리'!$A$6:$A$60,">="&B6,'클럭 정리'!$A$6:$A$60,"<="&C6) | H6: =G6*'클럭 정리'!$B$2/100
A7: 병렬도 6 분할 5 전체 | B7: 46238.488 | C7: 46238.488 | D7: =(C7-B7)*86400 | E7: 워커(호출마다 새 풀)+main | F7: =COUNTIFS('클럭 정리'!$A$6:$A$60,">="&B7,'클럭 정리'!$A$6:$A$60,"<="&C7) | G7: =AVERAGEIFS('클럭 정리'!$N$6:$N$60,'클럭 정리'!$A$6:$A$60,">="&B7,'클럭 정리'!$A$6:$A$60,"<="&C7) | H7: =G7*'클럭 정리'!$B$2/100
A8: 병렬도 6 분할 5 워밍업 | B8: 46238.488 | C8: 46238.488 | D8: =(C8-B8)*86400 | E8: 워커 (IMPLOG 기록 없음) | F8: =COUNTIFS('클럭 정리'!$A$6:$A$60,">="&B8,'클럭 정리'!$A$6:$A$60,"<="&C8) | G8: =AVERAGEIFS('클럭 정리'!$N$6:$N$60,'클럭 정리'!$A$6:$A$60,">="&B8,'클럭 정리'!$A$6:$A$60,"<="&C8) | H8: =G8*'클럭 정리'!$B$2/100
A9: 병렬도 6 분할 5 측정 1회차 | B9: 46238.488 | C9: 46238.488 | D9: =(C9-B9)*86400 | E9: ForkJoinPool-3-worker-1, ForkJoinPool-3-worker-2, ForkJoinPool-3-worker-3, ForkJoinPool-3-worker-4, ForkJoinPool-3-worker-5, ForkJoinPool-3-worker-6 + main(스캔 사이 순차 구간) | F9: =COUNTIFS('클럭 정리'!$A$6:$A$60,">="&B9,'클럭 정리'!$A$6:$A$60,"<="&C9) | G9: =AVERAGEIFS('클럭 정리'!$N$6:$N$60,'클럭 정리'!$A$6:$A$60,">="&B9,'클럭 정리'!$A$6:$A$60,"<="&C9) | H9: =G9*'클럭 정리'!$B$2/100
A10: 병렬도 6 분할 5 측정 2회차 | B10: 46238.488 | C10: 46238.488 | D10: =(C10-B10)*86400 | E10: ForkJoinPool-4-worker-1, ForkJoinPool-4-worker-2, ForkJoinPool-4-worker-3, ForkJoinPool-4-worker-4, ForkJoinPool-4-worker-5 + main(스캔 사이 순차 구간) | F10: =COUNTIFS('클럭 정리'!$A$6:$A$60,">="&B10,'클럭 정리'!$A$6:$A$60,"<="&C10) | G10: =AVERAGEIFS('클럭 정리'!$N$6:$N$60,'클럭 정리'!$A$6:$A$60,">="&B10,'클럭 정리'!$A$6:$A$60,"<="&C10) | H10: =G10*'클럭 정리'!$B$2/100
A11: 병렬도 6 분할 5 측정 3회차 | B11: 46238.488 | C11: 46238.488 | D11: =(C11-B11)*86400 | E11: ForkJoinPool-5-worker-1, ForkJoinPool-5-worker-2, ForkJoinPool-5-worker-3, ForkJoinPool-5-worker-4, ForkJoinPool-5-worker-5 + main(스캔 사이 순차 구간) | F11: =COUNTIFS('클럭 정리'!$A$6:$A$60,">="&B11,'클럭 정리'!$A$6:$A$60,"<="&C11) | G11: =AVERAGEIFS('클럭 정리'!$N$6:$N$60,'클럭 정리'!$A$6:$A$60,">="&B11,'클럭 정리'!$A$6:$A$60,"<="&C11) | H11: =G11*'클럭 정리'!$B$2/100
A12: 병렬도 6 분할 5 측정 4회차 | B12: 46238.488 | C12: 46238.488 | D12: =(C12-B12)*86400 | E12: ForkJoinPool-6-worker-1, ForkJoinPool-6-worker-2, ForkJoinPool-6-worker-3, ForkJoinPool-6-worker-4, ForkJoinPool-6-worker-5 + main(스캔 사이 순차 구간) | F12: =COUNTIFS('클럭 정리'!$A$6:$A$60,">="&B12,'클럭 정리'!$A$6:$A$60,"<="&C12) | G12: =AVERAGEIFS('클럭 정리'!$N$6:$N$60,'클럭 정리'!$A$6:$A$60,">="&B12,'클럭 정리'!$A$6:$A$60,"<="&C12) | H12: =G12*'클럭 정리'!$B$2/100
A13: 병렬도 6 분할 5 측정 5회차 | B13: 46238.488 | C13: 46238.488 | D13: =(C13-B13)*86400 | E13: ForkJoinPool-7-worker-1, ForkJoinPool-7-worker-2, ForkJoinPool-7-worker-3, ForkJoinPool-7-worker-4, ForkJoinPool-7-worker-5, ForkJoinPool-7-worker-6 + main(스캔 사이 순차 구간) | F13: =COUNTIFS('클럭 정리'!$A$6:$A$60,">="&B13,'클럭 정리'!$A$6:$A$60,"<="&C13) | G13: =AVERAGEIFS('클럭 정리'!$N$6:$N$60,'클럭 정리'!$A$6:$A$60,">="&B13,'클럭 정리'!$A$6:$A$60,"<="&C13) | H13: =G13*'클럭 정리'!$B$2/100
A14: 병렬도 6 분할 5 워커별 CPU 읽기 실행 | B14: 46238.488 | C14: 46238.488 | D14: =(C14-B14)*86400 | E14: ForkJoinPool-8-worker-4, ForkJoinPool-8-worker-2, ForkJoinPool-8-worker-1, ForkJoinPool-8-worker-3, ForkJoinPool-8-worker-6, ForkJoinPool-8-worker-5 + main | F14: =COUNTIFS('클럭 정리'!$A$6:$A$60,">="&B14,'클럭 정리'!$A$6:$A$60,"<="&C14) | G14: =AVERAGEIFS('클럭 정리'!$N$6:$N$60,'클럭 정리'!$A$6:$A$60,">="&B14,'클럭 정리'!$A$6:$A$60,"<="&C14) | H14: =G14*'클럭 정리'!$B$2/100
A15: 병렬도 12 분할 5 전체 | B15: 46238.488 | C15: 46238.488 | D15: =(C15-B15)*86400 | E15: 워커(호출마다 새 풀)+main | F15: =COUNTIFS('클럭 정리'!$A$6:$A$60,">="&B15,'클럭 정리'!$A$6:$A$60,"<="&C15) | G15: =AVERAGEIFS('클럭 정리'!$N$6:$N$60,'클럭 정리'!$A$6:$A$60,">="&B15,'클럭 정리'!$A$6:$A$60,"<="&C15) | H15: =G15*'클럭 정리'!$B$2/100
A16: 병렬도 12 분할 5 워밍업 | B16: 46238.488 | C16: 46238.488 | D16: =(C16-B16)*86400 | E16: 워커 (IMPLOG 기록 없음) | F16: =COUNTIFS('클럭 정리'!$A$6:$A$60,">="&B16,'클럭 정리'!$A$6:$A$60,"<="&C16) | G16: =AVERAGEIFS('클럭 정리'!$N$6:$N$60,'클럭 정리'!$A$6:$A$60,">="&B16,'클럭 정리'!$A$6:$A$60,"<="&C16) | H16: =G16*'클럭 정리'!$B$2/100
A17: 병렬도 12 분할 5 측정 1회차 | B17: 46238.488 | C17: 46238.488 | D17: =(C17-B17)*86400 | E17: ForkJoinPool-11-worker-1, ForkJoinPool-11-worker-11, ForkJoinPool-11-worker-12, ForkJoinPool-11-worker-2, ForkJoinPool-11-worker-3, ForkJoinPool-11-worker-4, ForkJoinPool-11-worker-5, ForkJoinPool-11-worker-7, ForkJoinPool-11-worker-9 + main(스캔 사이 순차 구간) | F17: =COUNTIFS('클럭 정리'!$A$6:$A$60,">="&B17,'클럭 정리'!$A$6:$A$60,"<="&C17) | G17: =AVERAGEIFS('클럭 정리'!$N$6:$N$60,'클럭 정리'!$A$6:$A$60,">="&B17,'클럭 정리'!$A$6:$A$60,"<="&C17) | H17: =G17*'클럭 정리'!$B$2/100
... A22: 병렬도 12 분할 5 워커별 CPU 읽기 실행 | B22: 46238.488 | C22: 46238.488 | D22: =(C22-B22)*86400 | E22: ForkJoinPool-16-worker-3, ForkJoinPool-16-worker-1, ForkJoinPool-16-worker-11, ForkJoinPool-16-worker-12, ForkJoinPool-16-worker-2, ForkJoinPool-16-worker-10, ForkJoinPool-16-worker-8, ForkJoinPool-16-worker-4, ForkJoinPool-16-worker-5, ForkJoinPool-16-worker-9, ForkJoinPool-16-worker-6, ForkJoinPool-16-worker-7 + main | F22: =COUNTIFS('클럭 정리'!$A$6:$A$60,">="&B22,'클럭 정리'!$A$6:$A$60,"<="&C22) | G22: =AVERAGEIFS('클럭 정리'!$N$6:$N$60,'클럭 정리'!$A$6:$A$60,">="&B22,'클럭 정리'!$A$6:$A$60,"<="&C22) | H22: =G22*'클럭 정리'!$B$2/100

Sheet 스레드별 클럭
A1: 측정 회차 구간 안의 스레드별 활동 창과 클럭, 그리고 풀별 클럭 표본 매핑
A2: 활동 창의 출처: 워커는 IMPLOG leaf(첫 말단 시작 ~ 마지막 말단 시작+4중 루프), main은 IMPLOG scan이다. 활동 시간 합은 워커가 4중 루프 경과 시간 합이고, main은 그 회차의 mainCPU(IMPLOG run 레코드, CPU 시간)다. 말단이 2개 이상 겹치면 경과 시간 뺄셈으로는 main 몫이 나오지 않아 실측 CPU 시간으로 바꿨다(2026-08-04). run 레코드가 없는 옛 로그는 main의 이 칸이 빈 칸이고, mainCPU는 Windows 해상도(15.625ms) 계단이라 0으로 찍힐 수 있다.
A3: 클럭 값은 그 창에 걸린 표본의 전체 프로세서 평균이다. 스레드가 어느 논리 프로세서에서 돌았는지는 기록되지 않으므로 특정 코어의 클럭이 아니다. 워커별 CPU 읽기 실행의 풀은 IMPLOG가 꺼져 있어 이 시트에 없다.
A5: 구간 | B5: 회차 | C5: 스레드 | D5: 역할 | E5: 활동 시작 | F5: 활동 끝 | G5: 처리 수(말단/스캔) | H5: 활동 시간 합(ms) | I5: 표본 수(개) | J5: 평균 클럭(%) | K5: 평균 클럭(GHz)
A6: 병렬도 6 분할 5 | B6: 1 | C6: ForkJoinPool-3-worker-1 | D6: 워커 | E6: 46238.488 | F6: 46238.488 | G6: 45 | H6: 1269.8613 | I6: =COUNTIFS('클럭 정리'!$A$6:$A$60,">="&E6,'클럭 정리'!$A$6:$A$60,"<="&F6) | J6: =AVERAGEIFS('클럭 정리'!$N$6:$N$60,'클럭 정리'!$A$6:$A$60,">="&E6,'클럭 정리'!$A$6:$A$60,"<="&F6) | K6: =J6*'클럭 정리'!$B$2/100
A7: 병렬도 6 분할 5 | B7: 1 | C7: ForkJoinPool-3-worker-2 | D7: 워커 | E7: 46238.488 | F7: 46238.488 | G7: 45 | H7: 1289.2893 | I7: =COUNTIFS('클럭 정리'!$A$6:$A$60,">="&E7,'클럭 정리'!$A$6:$A$60,"<="&F7) | J7: =AVERAGEIFS('클럭 정리'!$N$6:$N$60,'클럭 정리'!$A$6:$A$60,">="&E7,'클럭 정리'!$A$6:$A$60,"<="&F7) | K7: =J7*'클럭 정리'!$B$2/100
A8: 병렬도 6 분할 5 | B8: 1 | C8: ForkJoinPool-3-worker-3 | D8: 워커 | E8: 46238.488 | F8: 46238.488 | G8: 45 | H8: 1272.9217 | I8: =COUNTIFS('클럭 정리'!$A$6:$A$60,">="&E8,'클럭 정리'!$A$6:$A$60,"<="&F8) | J8: =AVERAGEIFS('클럭 정리'!$N$6:$N$60,'클럭 정리'!$A$6:$A$60,">="&E8,'클럭 정리'!$A$6:$A$60,"<="&F8) | K8: =J8*'클럭 정리'!$B$2/100
A9: 병렬도 6 분할 5 | B9: 1 | C9: ForkJoinPool-3-worker-4 | D9: 워커 | E9: 46238.488 | F9: 46238.488 | G9: 1 | H9: 25.713 | I9: =COUNTIFS('클럭 정리'!$A$6:$A$60,">="&E9,'클럭 정리'!$A$6:$A$60,"<="&F9) | J9: =AVERAGEIFS('클럭 정리'!$N$6:$N$60,'클럭 정리'!$A$6:$A$60,">="&E9,'클럭 정리'!$A$6:$A$60,"<="&F9) | K9: =J9*'클럭 정리'!$B$2/100
A10: 병렬도 6 분할 5 | B10: 1 | C10: ForkJoinPool-3-worker-5 | D10: 워커 | E10: 46238.488 | F10: 46238.488 | G10: 45 | H10: 1262.2022 | I10: =COUNTIFS('클럭 정리'!$A$6:$A$60,">="&E10,'클럭 정리'!$A$6:$A$60,"<="&F10) | J10: =AVERAGEIFS('클럭 정리'!$N$6:$N$60,'클럭 정리'!$A$6:$A$60,">="&E10,'클럭 정리'!$A$6:$A$60,"<="&F10) | K10: =J10*'클럭 정리'!$B$2/100
A11: 병렬도 6 분할 5 | B11: 1 | C11: ForkJoinPool-3-worker-6 | D11: 워커 | E11: 46238.488 | F11: 46238.488 | G11: 44 | H11: 1217.3112 | I11: =COUNTIFS('클럭 정리'!$A$6:$A$60,">="&E11,'클럭 정리'!$A$6:$A$60,"<="&F11) | J11: =AVERAGEIFS('클럭 정리'!$N$6:$N$60,'클럭 정리'!$A$6:$A$60,">="&E11,'클럭 정리'!$A$6:$A$60,"<="&F11) | K11: =J11*'클럭 정리'!$B$2/100
A12: 병렬도 6 분할 5 | B12: 1 | C12: main | D12: main (활동 시간 합 = 그 회차 mainCPU, 창은 워커와 겹침) | E12: 46238.488 | F12: 46238.488 | G12: 45 | H12: 0 | I12: =COUNTIFS('클럭 정리'!$A$6:$A$60,">="&E12,'클럭 정리'!$A$6:$A$60,"<="&F12) | J12: =AVERAGEIFS('클럭 정리'!$N$6:$N$60,'클럭 정리'!$A$6:$A$60,">="&E12,'클럭 정리'!$A$6:$A$60,"<="&F12) | K12: =J12*'클럭 정리'!$B$2/100
A13: 병렬도 6 분할 5 | B13: 2 | C13: ForkJoinPool-4-worker-1 | D13: 워커 | E13: 46238.488 | F13: 46238.488 | G13: 45 | H13: 1232.2868 | I13: =COUNTIFS('클럭 정리'!$A$6:$A$60,">="&E13,'클럭 정리'!$A$6:$A$60,"<="&F13) | J13: =AVERAGEIFS('클럭 정리'!$N$6:$N$60,'클럭 정리'!$A$6:$A$60,">="&E13,'클럭 정리'!$A$6:$A$60,"<="&F13) | K13: =J13*'클럭 정리'!$B$2/100
A14: 병렬도 6 분할 5 | B14: 2 | C14: ForkJoinPool-4-worker-2 | D14: 워커 | E14: 46238.488 | F14: 46238.488 | G14: 45 | H14: 1243.2456 | I14: =COUNTIFS('클럭 정리'!$A$6:$A$60,">="&E14,'클럭 정리'!$A$6:$A$60,"<="&F14) | J14: =AVERAGEIFS('클럭 정리'!$N$6:$N$60,'클럭 정리'!$A$6:$A$60,">="&E14,'클럭 정리'!$A$6:$A$60,"<="&F14) | K14: =J14*'클럭 정리'!$B$2/100
A15: 병렬도 6 분할 5 | B15: 2 | C15: ForkJoinPool-4-worker-3 | D15: 워커 | E15: 46238.488 | F15: 46238.488 | G15: 45 | H15: 1250.0566 | I15: =COUNTIFS('클럭 정리'!$A$6:$A$60,">="&E15,'클럭 정리'!$A$6:$A$60,"<="&F15) | J15: =AVERAGEIFS('클럭 정리'!$N$6:$N$60,'클럭 정리'!$A$6:$A$60,">="&E15,'클럭 정리'!$A$6:$A$60,"<="&F15) | K15: =J15*'클럭 정리'!$B$2/100
A16: 병렬도 6 분할 5 | B16: 2 | C16: ForkJoinPool-4-worker-4 | D16: 워커 | E16: 46238.488 | F16: 46238.488 | G16: 45 | H16: 1251.2265 | I16: =COUNTIFS('클럭 정리'!$A$6:$A$60,">="&E16,'클럭 정리'!$A$6:$A$60,"<="&F16) | J16: =AVERAGEIFS('클럭 정리'!$N$6:$N$60,'클럭 정리'!$A$6:$A$60,">="&E16,'클럭 정리'!$A$6:$A$60,"<="&F16) | K16: =J16*'클럭 정리'!$B$2/100
A17: 병렬도 6 분할 5 | B17: 2 | C17: ForkJoinPool-4-worker-5 | D17: 워커 | E17: 46238.488 | F17: 46238.488 | G17: 45 | H17: 1239.0812 | I17: =COUNTIFS('클럭 정리'!$A$6:$A$60,">="&E17,'클럭 정리'!$A$6:$A$60,"<="&F17) | J17: =AVERAGEIFS('클럭 정리'!$N$6:$N$60,'클럭 정리'!$A$6:$A$60,">="&E17,'클럭 정리'!$A$6:$A$60,"<="&F17) | K17: =J17*'클럭 정리'!$B$2/100
... A93: 병렬도 12 분할 5 | B93: 5 | C93: main | D93: main (활동 시간 합 = 그 회차 mainCPU, 창은 워커와 겹침) | E93: 46238.488 | F93: 46238.488 | G93: 45 | H93: 15.625 | I93: =COUNTIFS('클럭 정리'!$A$6:$A$60,">="&E93,'클럭 정리'!$A$6:$A$60,"<="&F93) | J93: =AVERAGEIFS('클럭 정리'!$N$6:$N$60,'클럭 정리'!$A$6:$A$60,">="&E93,'클럭 정리'!$A$6:$A$60,"<="&F93) | K93: =J93*'클럭 정리'!$B$2/100
A96: 풀·main별 클럭 표본 매핑
A97: 행 하나가 (풀 또는 main, 그 활동 창에 걸린 클럭 표본 1개)다. 표본 값은 클럭 정리 시트의 해당 행을 참조한다. main의 창은 그 회차 스캔 전체라 같은 회차 풀과 같은 표본에 걸린다.
A98: 구간 | B98: 회차 | C98: 풀/스레드 | D98: 활동 시작 | E98: 활동 끝 | F98: 표본 시각 | G98: 표본 클럭(%) | H98: 표본 클럭(GHz)
A99: 병렬도 6 분할 5 | B99: 1 | C99: ForkJoinPool-3 | D99: 46238.488 | E99: 46238.488 | F99: ='클럭 정리'!A35 | G99: ='클럭 정리'!N35 | H99: ='클럭 정리'!O35
A100: 병렬도 6 분할 5 | B100: 1 | C100: main | D100: 46238.488 | E100: 46238.488 | F100: ='클럭 정리'!A35 | G100: ='클럭 정리'!N35 | H100: ='클럭 정리'!O35
A101: 병렬도 6 분할 5 | B101: 2 | C101: ForkJoinPool-4 | D101: 46238.488 | E101: 46238.488 | F101: ='클럭 정리'!A36 | G101: ='클럭 정리'!N36 | H101: ='클럭 정리'!O36
A102: 병렬도 6 분할 5 | B102: 2 | C102: main | D102: 46238.488 | E102: 46238.488 | F102: ='클럭 정리'!A36 | G102: ='클럭 정리'!N36 | H102: ='클럭 정리'!O36
A103: 병렬도 6 분할 5 | B103: 3 | C103: ForkJoinPool-5 | D103: 46238.488 | E103: 46238.488 | F103: ='클럭 정리'!A37 | G103: ='클럭 정리'!N37 | H103: ='클럭 정리'!O37
A104: 병렬도 6 분할 5 | B104: 3 | C104: ForkJoinPool-5 | D104: 46238.488 | E104: 46238.488 | F104: ='클럭 정리'!A38 | G104: ='클럭 정리'!N38 | H104: ='클럭 정리'!O38
A105: 병렬도 6 분할 5 | B105: 3 | C105: main | D105: 46238.488 | E105: 46238.488 | F105: ='클럭 정리'!A37 | G105: ='클럭 정리'!N37 | H105: ='클럭 정리'!O37
A106: 병렬도 6 분할 5 | B106: 3 | C106: main | D106: 46238.488 | E106: 46238.488 | F106: ='클럭 정리'!A38 | G106: ='클럭 정리'!N38 | H106: ='클럭 정리'!O38
A107: 병렬도 6 분할 5 | B107: 4 | C107: ForkJoinPool-6 | D107: 46238.488 | E107: 46238.488 | F107: ='클럭 정리'!A39 | G107: ='클럭 정리'!N39 | H107: ='클럭 정리'!O39
A108: 병렬도 6 분할 5 | B108: 4 | C108: main | D108: 46238.488 | E108: 46238.488 | F108: ='클럭 정리'!A39 | G108: ='클럭 정리'!N39 | H108: ='클럭 정리'!O39
A109: 병렬도 6 분할 5 | B109: 5 | C109: ForkJoinPool-7 | D109: 46238.488 | E109: 46238.488 | F109: ='클럭 정리'!A40 | G109: ='클럭 정리'!N40 | H109: ='클럭 정리'!O40
A110: 병렬도 6 분할 5 | B110: 5 | C110: main | D110: 46238.488 | E110: 46238.488 | F110: ='클럭 정리'!A40 | G110: ='클럭 정리'!N40 | H110: ='클럭 정리'!O40
A111: 병렬도 12 분할 5 | B111: 1 | C111: ForkJoinPool-11 | D111: 46238.488 | E111: 46238.488 | F111: ='클럭 정리'!A45 | G111: ='클럭 정리'!N45 | H111: ='클럭 정리'!O45
A112: 병렬도 12 분할 5 | B112: 1 | C112: ForkJoinPool-11 | D112: 46238.488 | E112: 46238.488 | F112: ='클럭 정리'!A46 | G112: ='클럭 정리'!N46 | H112: ='클럭 정리'!O46
A113: 병렬도 12 분할 5 | B113: 1 | C113: main | D113: 46238.488 | E113: 46238.488 | F113: ='클럭 정리'!A45 | G113: ='클럭 정리'!N45 | H113: ='클럭 정리'!O45
A114: 병렬도 12 분할 5 | B114: 1 | C114: main | D114: 46238.488 | E114: 46238.488 | F114: ='클럭 정리'!A46 | G114: ='클럭 정리'!N46 | H114: ='클럭 정리'!O46
A115: 병렬도 12 분할 5 | B115: 2 | C115: ForkJoinPool-12 | D115: 46238.488 | E115: 46238.488 | F115: ='클럭 정리'!A47 | G115: ='클럭 정리'!N47 | H115: ='클럭 정리'!O47
A116: 병렬도 12 분할 5 | B116: 2 | C116: main | D116: 46238.488 | E116: 46238.488 | F116: ='클럭 정리'!A47 | G116: ='클럭 정리'!N47 | H116: ='클럭 정리'!O47
A117: 병렬도 12 분할 5 | B117: 3 | C117: ForkJoinPool-13 | D117: 46238.488 | E117: 46238.488 | F117: ='클럭 정리'!A48 | G117: ='클럭 정리'!N48 | H117: ='클럭 정리'!O48
A118: 병렬도 12 분할 5 | B118: 3 | C118: main | D118: 46238.488 | E118: 46238.488 | F118: ='클럭 정리'!A48 | G118: ='클럭 정리'!N48 | H118: ='클럭 정리'!O48
...

Sheet 회차별 측정값
A1: 측정 회차별 원값 (IMPLOG run 레코드). 프로브 표의 행은 5회 평균이고, 이 시트는 그 5회 각각이다
A2: busyCore와 speedup은 파생값이라 로그에 없고 여기서 수식으로 계산한다. busyCore는 procCPU를 elapsed로 나눈 값, speedup은 순차 elapsed의 5회 평균을 그 행의 elapsed로 나눈 값이다. 스레드 CPU 시간(mainCPU 등)은 Windows 해상도(15.625ms) 계단이라 작은 값은 0으로 찍힌다.
A4: 구현 | B4: 병렬도 | C4: 분할 | D4: 회차 | E4: elapsed(ms) | F4: procCPU(ms) | G4: busyCore(개) | H4: mainCPU(ms) | I4: workerCPU(ms) | J4: 기타 자바(ms) | K4: 자바 아닌(ms) | L4: GC(ms) | M4: speedup(배)
A5: 순차 | B5: - | C5: - | D5: 1 | E5: 3254.5945 | F5: 3234.375 | G5: =F5/E5 | H5: 3234.375 | I5: 0 | J5: 0 | K5: -15.625 | L5: 19
A6: 순차 | B6: - | C6: - | D6: 2 | E6: 3448.1961 | F6: 3609.375 | G6: =F6/E6 | H6: 3375 | I6: 0 | J6: 0 | K6: 234.375 | L6: 18
A7: 순차 | B7: - | C7: - | D7: 3 | E7: 3429.542 | F7: 3468.75 | G7: =F7/E7 | H7: 3390.625 | I7: 0 | J7: 0 | K7: 78.125 | L7: 16
A8: 순차 | B8: - | C8: - | D8: 4 | E8: 3424.1924 | F8: 3406.25 | G8: =F8/E8 | H8: 3390.625 | I8: 0 | J8: 0 | K8: 15.625 | L8: 19
A9: 순차 | B9: - | C9: - | D9: 5 | E9: 3413.5702 | F9: 3406.25 | G9: =F9/E9 | H9: 3390.625 | I9: 0 | J9: 0 | K9: 15.625 | L9: 17
A10: 병렬 | B10: 6 | C10: 5 | D10: 1 | E10: 1386.9551 | F10: 6984.375 | G10: =F10/E10 | H10: 0 | I10: 6187.5 | J10: 0 | K10: 796.875 | L10: 14 | M10: =AVERAGEIFS($E$5:$E$19,$A$5:$A$19,"순차")/E10
A11: 병렬 | B11: 6 | C11: 5 | D11: 2 | E11: 1345.0022 | F11: 5968.75 | G11: =F11/E11 | H11: 31.25 | I11: 5906.25 | J11: 0 | K11: 31.25 | L11: 15 | M11: =AVERAGEIFS($E$5:$E$19,$A$5:$A$19,"순차")/E11
A12: 병렬 | B12: 6 | C12: 5 | D12: 3 | E12: 1339.1753 | F12: 6203.125 | G12: =F12/E12 | H12: 0 | I12: 6187.5 | J12: 0 | K12: 15.625 | L12: 15 | M12: =AVERAGEIFS($E$5:$E$19,$A$5:$A$19,"순차")/E12
A13: 병렬 | B13: 6 | C13: 5 | D13: 4 | E13: 1324.4941 | F13: 5953.125 | G13: =F13/E13 | H13: 0 | I13: 5906.25 | J13: 0 | K13: 46.875 | L13: 14 | M13: =AVERAGEIFS($E$5:$E$19,$A$5:$A$19,"순차")/E13
A14: 병렬 | B14: 6 | C14: 5 | D14: 5 | E14: 1347.5862 | F14: 6343.75 | G14: =F14/E14 | H14: 0 | I14: 6328.125 | J14: 0 | K14: 15.625 | L14: 16 | M14: =AVERAGEIFS($E$5:$E$19,$A$5:$A$19,"순차")/E14
A15: 병렬 | B15: 12 | C15: 5 | D15: 1 | E15: 1341.817 | F15: 6156.25 | G15: =F15/E15 | H15: 15.625 | I15: 5968.75 | J15: 0 | K15: 171.875 | L15: 12 | M15: =AVERAGEIFS($E$5:$E$19,$A$5:$A$19,"순차")/E15
A16: 병렬 | B16: 12 | C16: 5 | D16: 2 | E16: 1326.9953 | F16: 6109.375 | G16: =F16/E16 | H16: 0 | I16: 5937.5 | J16: 0 | K16: 171.875 | L16: 13 | M16: =AVERAGEIFS($E$5:$E$19,$A$5:$A$19,"순차")/E16
A17: 병렬 | B17: 12 | C17: 5 | D17: 3 | E17: 1352.3776 | F17: 6062.5 | G17: =F17/E17 | H17: 0 | I17: 6015.625 | J17: 0 | K17: 46.875 | L17: 14 | M17: =AVERAGEIFS($E$5:$E$19,$A$5:$A$19,"순차")/E17
A18: 병렬 | B18: 12 | C18: 5 | D18: 4 | E18: 1352.6991 | F18: 6390.625 | G18: =F18/E18 | H18: 15.625 | I18: 6359.375 | J18: 0 | K18: 15.625 | L18: 12 | M18: =AVERAGEIFS($E$5:$E$19,$A$5:$A$19,"순차")/E18
A19: 병렬 | B19: 12 | C19: 5 | D19: 5 | E19: 1340.4208 | F19: 6218.75 | G19: =F19/E19 | H19: 15.625 | I19: 6203.125 | J19: 0 | K19: 0 | L19: 14 | M19: =AVERAGEIFS($E$5:$E$19,$A$5:$A$19,"순차")/E19

Sheet 차트
A1: 이 시트의 값: '구간과 스레드 매핑' 시트의 평균 클럭(GHz) 열이다. 수식 참조로 그대로 가져왔다
A2: 차트: 전체 추이 선(전체 평균과 스레드별 선), 구간별 평균 막대, 측정 회차마다 스레드별 클럭 선 그래프다. 스레드별 선은 그 스레드의 활동 창에 걸린 표본만 그린다. 분할 1처럼 창이 겹치면 선도 겹친다. 그래프의 원천 표는 '차트 데이터' 시트에 있다
A3: 구간 종류 | B3: 순차 | C3: 병렬도 6 분할 5 | D3: 병렬도 12 분할 5
A4: 전체 | B4: ='구간과 스레드 매핑'!H6 | C4: ='구간과 스레드 매핑'!H7 | D4: ='구간과 스레드 매핑'!H15
A5: 워밍업 | C5: ='구간과 스레드 매핑'!H8 | D5: ='구간과 스레드 매핑'!H16
A6: 측정 1회차 | C6: ='구간과 스레드 매핑'!H9 | D6: ='구간과 스레드 매핑'!H17
A7: 측정 2회차 | C7: ='구간과 스레드 매핑'!H10 | D7: ='구간과 스레드 매핑'!H18
A8: 측정 3회차 | C8: ='구간과 스레드 매핑'!H11 | D8: ='구간과 스레드 매핑'!H19
A9: 측정 4회차 | C9: ='구간과 스레드 매핑'!H12 | D9: ='구간과 스레드 매핑'!H20
A10: 측정 5회차 | C10: ='구간과 스레드 매핑'!H13 | D10: ='구간과 스레드 매핑'!H21
A11: 워커별 CPU 읽기 실행 | C11: ='구간과 스레드 매핑'!H14 | D11: ='구간과 스레드 매핑'!H22

Sheet 차트 데이터
A1: 차트 시트 그래프들의 원천 표다. 값은 전부 '클럭 정리' 시트를 참조하는 수식이고, 여기서는 보기만 한다
A3: 병렬도 6 분할 5 측정 1회차 (스레드별 클럭, GHz) | O3: 전체 추이 데이터 (스레드별 선용, GHz)
A4: 시각 | B4: ForkJoinPool-3-worker-1 | C4: ForkJoinPool-3-worker-2 | D4: ForkJoinPool-3-worker-3 | E4: ForkJoinPool-3-worker-4 | F4: ForkJoinPool-3-worker-5 | G4: ForkJoinPool-3-worker-6 | H4: main | O4: 시각 | P4: 전체 평균 | Q4: ForkJoinPool-3-worker-1 | R4: ForkJoinPool-3-worker-2 | S4: ForkJoinPool-3-worker-3 | T4: ForkJoinPool-3-worker-4 | U4: ForkJoinPool-3-worker-5 | V4: ForkJoinPool-3-worker-6 | W4: main | X4: ForkJoinPool-4-worker-1 | Y4: ForkJoinPool-4-worker-2 | Z4: ForkJoinPool-4-worker-3 | AA4: ForkJoinPool-4-worker-4 | AB4: ForkJoinPool-4-worker-5 | AC4: ForkJoinPool-5-worker-1 | AD4: ForkJoinPool-5-worker-2 | AE4: ForkJoinPool-5-worker-3 | AF4: ForkJoinPool-5-worker-4 | AG4: ForkJoinPool-5-worker-5 | AH4: ForkJoinPool-6-worker-1 | AI4: ForkJoinPool-6-worker-2 | AJ4: ForkJoinPool-6-worker-3 | AK4: ForkJoinPool-6-worker-4 | AL4: ForkJoinPool-6-worker-5 | AM4: ForkJoinPool-7-worker-1 | AN4: ForkJoinPool-7-worker-2 | AO4: ForkJoinPool-7-worker-3 | AP4: ForkJoinPool-7-worker-4 | AQ4: ForkJoinPool-7-worker-5 | AR4: ForkJoinPool-7-worker-6 | AS4: ForkJoinPool-11-worker-1 | AT4: ForkJoinPool-11-worker-11 | AU4: ForkJoinPool-11-worker-12 | AV4: ForkJoinPool-11-worker-2 | AW4: ForkJoinPool-11-worker-3 | AX4: ForkJoinPool-11-worker-4 | AY4: ForkJoinPool-11-worker-5 | AZ4: ForkJoinPool-11-worker-7 | BA4: ForkJoinPool-11-worker-9 | BB4: ForkJoinPool-12-worker-1 | BC4: ForkJoinPool-12-worker-12 | BD4: ForkJoinPool-12-worker-2 | BE4: ForkJoinPool-12-worker-3 | BF4: ForkJoinPool-12-worker-4 | BG4: ForkJoinPool-12-worker-5 | BH4: ForkJoinPool-12-worker-7 | BI4: ForkJoinPool-12-worker-8 | BJ4: ForkJoinPool-12-worker-9 | BK4: ForkJoinPool-13-worker-1 | BL4: ForkJoinPool-13-worker-10 | BM4: ForkJoinPool-13-worker-11 | BN4: ForkJoinPool-13-worker-12 | BO4: ForkJoinPool-13-worker-2 | BP4: ForkJoinPool-13-worker-3 | BQ4: ForkJoinPool-13-worker-4 | BR4: ForkJoinPool-13-worker-5 | BS4: ForkJoinPool-13-worker-7 | BT4: ForkJoinPool-13-worker-8 | BU4: ForkJoinPool-13-worker-9 | BV4: ForkJoinPool-14-worker-1 | BW4: ForkJoinPool-14-worker-10 | BX4: ForkJoinPool-14-worker-11 | BY4: ForkJoinPool-14-worker-12 | BZ4: ForkJoinPool-14-worker-2 | CA4: ForkJoinPool-14-worker-3 | CB4: ForkJoinPool-14-worker-4 | CC4: ForkJoinPool-14-worker-5 | CD4: ForkJoinPool-14-worker-6 | CE4: ForkJoinPool-14-worker-7 | CF4: ForkJoinPool-14-worker-9 | CG4: ForkJoinPool-15-worker-1 | CH4: ForkJoinPool-15-worker-10 | CI4: ForkJoinPool-15-worker-11 | CJ4: ForkJoinPool-15-worker-12 | CK4: ForkJoinPool-15-worker-2 | CL4: ForkJoinPool-15-worker-3 | CM4: ForkJoinPool-15-worker-4 | CN4: ForkJoinPool-15-worker-5 | CO4: ForkJoinPool-15-worker-7 | CP4: ForkJoinPool-15-worker-8 | CQ4: ForkJoinPool-15-worker-9
A5: ='클럭 정리'!A35 | B5: ='클럭 정리'!O35 | C5: ='클럭 정리'!O35 | D5: ='클럭 정리'!O35 | F5: ='클럭 정리'!O35 | G5: ='클럭 정리'!O35 | H5: ='클럭 정리'!O35 | O5: ='클럭 정리'!A6 | P5: ='클럭 정리'!O6
O6: ='클럭 정리'!A7 | P6: ='클럭 정리'!O7
A7: 병렬도 6 분할 5 측정 2회차 (스레드별 클럭, GHz) | O7: ='클럭 정리'!A8 | P7: ='클럭 정리'!O8
A8: 시각 | B8: ForkJoinPool-4-worker-1 | C8: ForkJoinPool-4-worker-2 | D8: ForkJoinPool-4-worker-3 | E8: ForkJoinPool-4-worker-4 | F8: ForkJoinPool-4-worker-5 | G8: main | O8: ='클럭 정리'!A9 | P8: ='클럭 정리'!O9
A9: ='클럭 정리'!A36 | B9: ='클럭 정리'!O36 | C9: ='클럭 정리'!O36 | D9: ='클럭 정리'!O36 | E9: ='클럭 정리'!O36 | F9: ='클럭 정리'!O36 | G9: ='클럭 정리'!O36 | O9: ='클럭 정리'!A10 | P9: ='클럭 정리'!O10
O10: ='클럭 정리'!A11 | P10: ='클럭 정리'!O11
A11: 병렬도 6 분할 5 측정 3회차 (스레드별 클럭, GHz) | O11: ='클럭 정리'!A12 | P11: ='클럭 정리'!O12
A12: 시각 | B12: ForkJoinPool-5-worker-1 | C12: ForkJoinPool-5-worker-2 | D12: ForkJoinPool-5-worker-3 | E12: ForkJoinPool-5-worker-4 | F12: ForkJoinPool-5-worker-5 | G12: main | O12: ='클럭 정리'!A13 | P12: ='클럭 정리'!O13
A13: ='클럭 정리'!A37 | B13: ='클럭 정리'!O37 | C13: ='클럭 정리'!O37 | D13: ='클럭 정리'!O37 | E13: ='클럭 정리'!O37 | F13: ='클럭 정리'!O37 | G13: ='클럭 정리'!O37 | O13: ='클럭 정리'!A14 | P13: ='클럭 정리'!O14
A14: ='클럭 정리'!A38 | B14: ='클럭 정리'!O38 | C14: ='클럭 정리'!O38 | D14: ='클럭 정리'!O38 | E14: ='클럭 정리'!O38 | F14: ='클럭 정리'!O38 | G14: ='클럭 정리'!O38 | O14: ='클럭 정리'!A15 | P14: ='클럭 정리'!O15
O15: ='클럭 정리'!A16 | P15: ='클럭 정리'!O16
A16: 병렬도 6 분할 5 측정 4회차 (스레드별 클럭, GHz) | O16: ='클럭 정리'!A17 | P16: ='클럭 정리'!O17
A17: 시각 | B17: ForkJoinPool-6-worker-1 | C17: ForkJoinPool-6-worker-2 | D17: ForkJoinPool-6-worker-3 | E17: ForkJoinPool-6-worker-4 | F17: ForkJoinPool-6-worker-5 | G17: main | O17: ='클럭 정리'!A18 | P17: ='클럭 정리'!O18
A18: ='클럭 정리'!A39 | B18: ='클럭 정리'!O39 | C18: ='클럭 정리'!O39 | D18: ='클럭 정리'!O39 | E18: ='클럭 정리'!O39 | F18: ='클럭 정리'!O39 | G18: ='클럭 정리'!O39 | O18: ='클럭 정리'!A19 | P18: ='클럭 정리'!O19
O19: ='클럭 정리'!A20 | P19: ='클럭 정리'!O20
A20: 병렬도 6 분할 5 측정 5회차 (스레드별 클럭, GHz) | O20: ='클럭 정리'!A21 | P20: ='클럭 정리'!O21
A21: 시각 | B21: ForkJoinPool-7-worker-1 | C21: ForkJoinPool-7-worker-2 | D21: ForkJoinPool-7-worker-3 | E21: ForkJoinPool-7-worker-4 | F21: ForkJoinPool-7-worker-5 | G21: ForkJoinPool-7-worker-6 | H21: main | O21: ='클럭 정리'!A22 | P21: ='클럭 정리'!O22
A22: ='클럭 정리'!A40 | B22: ='클럭 정리'!O40 | C22: ='클럭 정리'!O40 | D22: ='클럭 정리'!O40 | F22: ='클럭 정리'!O40 | G22: ='클럭 정리'!O40 | H22: ='클럭 정리'!O40 | O22: ='클럭 정리'!A23 | P22: ='클럭 정리'!O23
O23: ='클럭 정리'!A24 | P23: ='클럭 정리'!O24
A24: 병렬도 12 분할 5 측정 1회차 (스레드별 클럭, GHz) | O24: ='클럭 정리'!A25 | P24: ='클럭 정리'!O25
A25: 시각 | B25: ForkJoinPool-11-worker-1 | C25: ForkJoinPool-11-worker-11 | D25: ForkJoinPool-11-worker-12 | E25: ForkJoinPool-11-worker-2 | F25: ForkJoinPool-11-worker-3 | G25: ForkJoinPool-11-worker-4 | H25: ForkJoinPool-11-worker-5 | I25: ForkJoinPool-11-worker-7 | J25: ForkJoinPool-11-worker-9 | K25: main | O25: ='클럭 정리'!A26 | P25: ='클럭 정리'!O26
A26: ='클럭 정리'!A45 | B26: ='클럭 정리'!O45 | C26: ='클럭 정리'!O45 | D26: ='클럭 정리'!O45 | G26: ='클럭 정리'!O45 | J26: ='클럭 정리'!O45 | K26: ='클럭 정리'!O45 | O26: ='클럭 정리'!A27 | P26: ='클럭 정리'!O27
A27: ='클럭 정리'!A46 | B27: ='클럭 정리'!O46 | C27: ='클럭 정리'!O46 | D27: ='클럭 정리'!O46 | G27: ='클럭 정리'!O46 | J27: ='클럭 정리'!O46 | K27: ='클럭 정리'!O46 | O27: ='클럭 정리'!A28 | P27: ='클럭 정리'!O28
O28: ='클럭 정리'!A29 | P28: ='클럭 정리'!O29
A29: 병렬도 12 분할 5 측정 2회차 (스레드별 클럭, GHz) | O29: ='클럭 정리'!A30 | P29: ='클럭 정리'!O30
A30: 시각 | B30: ForkJoinPool-12-worker-1 | C30: ForkJoinPool-12-worker-12 | D30: ForkJoinPool-12-worker-2 | E30: ForkJoinPool-12-worker-3 | F30: ForkJoinPool-12-worker-4 | G30: ForkJoinPool-12-worker-5 | H30: ForkJoinPool-12-worker-7 | I30: ForkJoinPool-12-worker-8 | J30: ForkJoinPool-12-worker-9 | K30: main | O30: ='클럭 정리'!A31 | P30: ='클럭 정리'!O31
A31: ='클럭 정리'!A47 | B31: ='클럭 정리'!O47 | C31: ='클럭 정리'!O47 | H31: ='클럭 정리'!O47 | I31: ='클럭 정리'!O47 | J31: ='클럭 정리'!O47 | K31: ='클럭 정리'!O47 | O31: ='클럭 정리'!A32 | P31: ='클럭 정리'!O32
O32: ='클럭 정리'!A33 | P32: ='클럭 정리'!O33
A33: 병렬도 12 분할 5 측정 3회차 (스레드별 클럭, GHz) | O33: ='클럭 정리'!A34 | P33: ='클럭 정리'!O34
A34: 시각 | B34: ForkJoinPool-13-worker-1 | C34: ForkJoinPool-13-worker-10 | D34: ForkJoinPool-13-worker-11 | E34: ForkJoinPool-13-worker-12 | F34: ForkJoinPool-13-worker-2 | G34: ForkJoinPool-13-worker-3 | H34: ForkJoinPool-13-worker-4 | I34: ForkJoinPool-13-worker-5 | J34: ForkJoinPool-13-worker-7 | K34: ForkJoinPool-13-worker-8 | L34: ForkJoinPool-13-worker-9 | M34: main | O34: ='클럭 정리'!A35 | P34: ='클럭 정리'!O35 | Q34: ='클럭 정리'!O35 | R34: ='클럭 정리'!O35 | S34: ='클럭 정리'!O35 | U34: ='클럭 정리'!O35 | V34: ='클럭 정리'!O35 | W34: ='클럭 정리'!O35
A35: ='클럭 정리'!A48 | B35: ='클럭 정리'!O48 | C35: ='클럭 정리'!O48 | D35: ='클럭 정리'!O48 | E35: ='클럭 정리'!O48 | F35: ='클럭 정리'!O48 | M35: ='클럭 정리'!O48 | O35: ='클럭 정리'!A36 | P35: ='클럭 정리'!O36 | W35: ='클럭 정리'!O36 | X35: ='클럭 정리'!O36 | Y35: ='클럭 정리'!O36 | Z35: ='클럭 정리'!O36 | AA35: ='클럭 정리'!O36 | AB35: ='클럭 정리'!O36
O36: ='클럭 정리'!A37 | P36: ='클럭 정리'!O37 | W36: ='클럭 정리'!O37 | AC36: ='클럭 정리'!O37 | AD36: ='클럭 정리'!O37 | AE36: ='클럭 정리'!O37 | AF36: ='클럭 정리'!O37 | AG36: ='클럭 정리'!O37
A37: 병렬도 12 분할 5 측정 4회차 (스레드별 클럭, GHz) | O37: ='클럭 정리'!A38 | P37: ='클럭 정리'!O38 | W37: ='클럭 정리'!O38 | AC37: ='클럭 정리'!O38 | AD37: ='클럭 정리'!O38 | AE37: ='클럭 정리'!O38 | AF37: ='클럭 정리'!O38 | AG37: ='클럭 정리'!O38
A38: 시각 | B38: ForkJoinPool-14-worker-1 | C38: ForkJoinPool-14-worker-10 | D38: ForkJoinPool-14-worker-11 | E38: ForkJoinPool-14-worker-12 | F38: ForkJoinPool-14-worker-2 | G38: ForkJoinPool-14-worker-3 | H38: ForkJoinPool-14-worker-4 | I38: ForkJoinPool-14-worker-5 | J38: ForkJoinPool-14-worker-6 | K38: ForkJoinPool-14-worker-7 | L38: ForkJoinPool-14-worker-9 | M38: main | O38: ='클럭 정리'!A39 | P38: ='클럭 정리'!O39 | W38: ='클럭 정리'!O39 | AH38: ='클럭 정리'!O39 | AI38: ='클럭 정리'!O39 | AJ38: ='클럭 정리'!O39 | AK38: ='클럭 정리'!O39 | AL38: ='클럭 정리'!O39
A39: ='클럭 정리'!A49 | B39: ='클럭 정리'!O49 | D39: ='클럭 정리'!O49 | E39: ='클럭 정리'!O49 | I39: ='클럭 정리'!O49 | L39: ='클럭 정리'!O49 | M39: ='클럭 정리'!O49 | O39: ='클럭 정리'!A40 | P39: ='클럭 정리'!O40 | W39: ='클럭 정리'!O40 | AM39: ='클럭 정리'!O40 | AN39: ='클럭 정리'!O40 | AO39: ='클럭 정리'!O40 | AQ39: ='클럭 정리'!O40 | AR39: ='클럭 정리'!O40
A40: ='클럭 정리'!A50 | B40: ='클럭 정리'!O50 | D40: ='클럭 정리'!O50 | E40: ='클럭 정리'!O50 | I40: ='클럭 정리'!O50 | L40: ='클럭 정리'!O50 | M40: ='클럭 정리'!O50 | O40: ='클럭 정리'!A41 | P40: ='클럭 정리'!O41
O41: ='클럭 정리'!A42 | P41: ='클럭 정리'!O42
...
